2023-07-09 11:21:05,623 INFO: [31m[1mWARNING: This is a development server. Do not use it in a production deployment. Use a production WSGI server instead.[0m
 * Running on http://127.0.0.1:5000
2023-07-09 11:21:05,623 INFO: [33mPress CTRL+C to quit[0m
2023-07-09 11:22:25,405 INFO: [31m[1mWARNING: This is a development server. Do not use it in a production deployment. Use a production WSGI server instead.[0m
 * Running on http://127.0.0.1:5000
2023-07-09 11:22:25,405 INFO: [33mPress CTRL+C to quit[0m
2023-07-09 11:30:11,685 INFO: [31m[1mWARNING: This is a development server. Do not use it in a production deployment. Use a production WSGI server instead.[0m
 * Running on http://127.0.0.1:5000
2023-07-09 11:30:11,685 INFO: [33mPress CTRL+C to quit[0m
2023-07-09 11:30:49,228 ERROR: Exception on /users [GET]
Traceback (most recent call last):
  File "/Users/chaitanyaarora/Desktop/projectone/attendance-env/lib/python3.11/site-packages/flask/app.py", line 2190, in wsgi_app
    response = self.full_dispatch_request()
               ^^^^^^^^^^^^^^^^^^^^^^^^^^^^
  File "/Users/chaitanyaarora/Desktop/projectone/attendance-env/lib/python3.11/site-packages/flask/app.py", line 1486, in full_dispatch_request
    rv = self.handle_user_exception(e)
         ^^^^^^^^^^^^^^^^^^^^^^^^^^^^^
  File "/Users/chaitanyaarora/Desktop/projectone/attendance-env/lib/python3.11/site-packages/flask/app.py", line 1482, in full_dispatch_request
    rv = self.preprocess_request()
         ^^^^^^^^^^^^^^^^^^^^^^^^^
  File "/Users/chaitanyaarora/Desktop/projectone/attendance-env/lib/python3.11/site-packages/flask/app.py", line 1974, in preprocess_request
    rv = self.ensure_sync(before_func)()
         ^^^^^^^^^^^^^^^^^^^^^^^^^^^^^^^
  File "/Users/chaitanyaarora/Desktop/projectone/app.py", line 81, in before_first_request
    create_first_user()
  File "/Users/chaitanyaarora/Desktop/projectone/app.py", line 68, in create_first_user
    user_count = User.query.count()
                 ^^^^
NameError: name 'User' is not defined
2023-07-09 11:30:49,232 INFO: 127.0.0.1 - - [09/Jul/2023 11:30:49] "[35m[1mGET /users HTTP/1.1[0m" 500 -
2023-07-09 11:30:49,321 ERROR: Exception on /favicon.ico [GET]
Traceback (most recent call last):
  File "/Users/chaitanyaarora/Desktop/projectone/attendance-env/lib/python3.11/site-packages/flask/app.py", line 2190, in wsgi_app
    response = self.full_dispatch_request()
               ^^^^^^^^^^^^^^^^^^^^^^^^^^^^
  File "/Users/chaitanyaarora/Desktop/projectone/attendance-env/lib/python3.11/site-packages/flask/app.py", line 1486, in full_dispatch_request
    rv = self.handle_user_exception(e)
         ^^^^^^^^^^^^^^^^^^^^^^^^^^^^^
  File "/Users/chaitanyaarora/Desktop/projectone/attendance-env/lib/python3.11/site-packages/flask/app.py", line 1482, in full_dispatch_request
    rv = self.preprocess_request()
         ^^^^^^^^^^^^^^^^^^^^^^^^^
  File "/Users/chaitanyaarora/Desktop/projectone/attendance-env/lib/python3.11/site-packages/flask/app.py", line 1974, in preprocess_request
    rv = self.ensure_sync(before_func)()
         ^^^^^^^^^^^^^^^^^^^^^^^^^^^^^^^
  File "/Users/chaitanyaarora/Desktop/projectone/app.py", line 81, in before_first_request
    create_first_user()
  File "/Users/chaitanyaarora/Desktop/projectone/app.py", line 68, in create_first_user
    user_count = User.query.count()
                 ^^^^
NameError: name 'User' is not defined
2023-07-09 11:30:49,322 INFO: 127.0.0.1 - - [09/Jul/2023 11:30:49] "[35m[1mGET /favicon.ico HTTP/1.1[0m" 500 -
2023-07-09 11:30:57,317 ERROR: Exception on /user [GET]
Traceback (most recent call last):
  File "/Users/chaitanyaarora/Desktop/projectone/attendance-env/lib/python3.11/site-packages/flask/app.py", line 2190, in wsgi_app
    response = self.full_dispatch_request()
               ^^^^^^^^^^^^^^^^^^^^^^^^^^^^
  File "/Users/chaitanyaarora/Desktop/projectone/attendance-env/lib/python3.11/site-packages/flask/app.py", line 1486, in full_dispatch_request
    rv = self.handle_user_exception(e)
         ^^^^^^^^^^^^^^^^^^^^^^^^^^^^^
  File "/Users/chaitanyaarora/Desktop/projectone/attendance-env/lib/python3.11/site-packages/flask/app.py", line 1482, in full_dispatch_request
    rv = self.preprocess_request()
         ^^^^^^^^^^^^^^^^^^^^^^^^^
  File "/Users/chaitanyaarora/Desktop/projectone/attendance-env/lib/python3.11/site-packages/flask/app.py", line 1974, in preprocess_request
    rv = self.ensure_sync(before_func)()
         ^^^^^^^^^^^^^^^^^^^^^^^^^^^^^^^
  File "/Users/chaitanyaarora/Desktop/projectone/app.py", line 81, in before_first_request
    create_first_user()
  File "/Users/chaitanyaarora/Desktop/projectone/app.py", line 68, in create_first_user
    user_count = User.query.count()
                 ^^^^
NameError: name 'User' is not defined
2023-07-09 11:30:57,319 INFO: 127.0.0.1 - - [09/Jul/2023 11:30:57] "[35m[1mGET /user HTTP/1.1[0m" 500 -
2023-07-09 11:30:57,363 ERROR: Exception on /favicon.ico [GET]
Traceback (most recent call last):
  File "/Users/chaitanyaarora/Desktop/projectone/attendance-env/lib/python3.11/site-packages/flask/app.py", line 2190, in wsgi_app
    response = self.full_dispatch_request()
               ^^^^^^^^^^^^^^^^^^^^^^^^^^^^
  File "/Users/chaitanyaarora/Desktop/projectone/attendance-env/lib/python3.11/site-packages/flask/app.py", line 1486, in full_dispatch_request
    rv = self.handle_user_exception(e)
         ^^^^^^^^^^^^^^^^^^^^^^^^^^^^^
  File "/Users/chaitanyaarora/Desktop/projectone/attendance-env/lib/python3.11/site-packages/flask/app.py", line 1482, in full_dispatch_request
    rv = self.preprocess_request()
         ^^^^^^^^^^^^^^^^^^^^^^^^^
  File "/Users/chaitanyaarora/Desktop/projectone/attendance-env/lib/python3.11/site-packages/flask/app.py", line 1974, in preprocess_request
    rv = self.ensure_sync(before_func)()
         ^^^^^^^^^^^^^^^^^^^^^^^^^^^^^^^
  File "/Users/chaitanyaarora/Desktop/projectone/app.py", line 81, in before_first_request
    create_first_user()
  File "/Users/chaitanyaarora/Desktop/projectone/app.py", line 68, in create_first_user
    user_count = User.query.count()
                 ^^^^
NameError: name 'User' is not defined
2023-07-09 11:30:57,364 INFO: 127.0.0.1 - - [09/Jul/2023 11:30:57] "[35m[1mGET /favicon.ico HTTP/1.1[0m" 500 -
2023-07-09 11:30:59,857 ERROR: Exception on /use [GET]
Traceback (most recent call last):
  File "/Users/chaitanyaarora/Desktop/projectone/attendance-env/lib/python3.11/site-packages/flask/app.py", line 2190, in wsgi_app
    response = self.full_dispatch_request()
               ^^^^^^^^^^^^^^^^^^^^^^^^^^^^
  File "/Users/chaitanyaarora/Desktop/projectone/attendance-env/lib/python3.11/site-packages/flask/app.py", line 1486, in full_dispatch_request
    rv = self.handle_user_exception(e)
         ^^^^^^^^^^^^^^^^^^^^^^^^^^^^^
  File "/Users/chaitanyaarora/Desktop/projectone/attendance-env/lib/python3.11/site-packages/flask/app.py", line 1482, in full_dispatch_request
    rv = self.preprocess_request()
         ^^^^^^^^^^^^^^^^^^^^^^^^^
  File "/Users/chaitanyaarora/Desktop/projectone/attendance-env/lib/python3.11/site-packages/flask/app.py", line 1974, in preprocess_request
    rv = self.ensure_sync(before_func)()
         ^^^^^^^^^^^^^^^^^^^^^^^^^^^^^^^
  File "/Users/chaitanyaarora/Desktop/projectone/app.py", line 81, in before_first_request
    create_first_user()
  File "/Users/chaitanyaarora/Desktop/projectone/app.py", line 68, in create_first_user
    user_count = User.query.count()
                 ^^^^
NameError: name 'User' is not defined
2023-07-09 11:30:59,858 INFO: 127.0.0.1 - - [09/Jul/2023 11:30:59] "[35m[1mGET /use HTTP/1.1[0m" 500 -
2023-07-09 11:30:59,900 ERROR: Exception on /favicon.ico [GET]
Traceback (most recent call last):
  File "/Users/chaitanyaarora/Desktop/projectone/attendance-env/lib/python3.11/site-packages/flask/app.py", line 2190, in wsgi_app
    response = self.full_dispatch_request()
               ^^^^^^^^^^^^^^^^^^^^^^^^^^^^
  File "/Users/chaitanyaarora/Desktop/projectone/attendance-env/lib/python3.11/site-packages/flask/app.py", line 1486, in full_dispatch_request
    rv = self.handle_user_exception(e)
         ^^^^^^^^^^^^^^^^^^^^^^^^^^^^^
  File "/Users/chaitanyaarora/Desktop/projectone/attendance-env/lib/python3.11/site-packages/flask/app.py", line 1482, in full_dispatch_request
    rv = self.preprocess_request()
         ^^^^^^^^^^^^^^^^^^^^^^^^^
  File "/Users/chaitanyaarora/Desktop/projectone/attendance-env/lib/python3.11/site-packages/flask/app.py", line 1974, in preprocess_request
    rv = self.ensure_sync(before_func)()
         ^^^^^^^^^^^^^^^^^^^^^^^^^^^^^^^
  File "/Users/chaitanyaarora/Desktop/projectone/app.py", line 81, in before_first_request
    create_first_user()
  File "/Users/chaitanyaarora/Desktop/projectone/app.py", line 68, in create_first_user
    user_count = User.query.count()
                 ^^^^
NameError: name 'User' is not defined
2023-07-09 11:30:59,901 INFO: 127.0.0.1 - - [09/Jul/2023 11:30:59] "[35m[1mGET /favicon.ico HTTP/1.1[0m" 500 -
2023-07-09 11:31:02,054 ERROR: Exception on / [GET]
Traceback (most recent call last):
  File "/Users/chaitanyaarora/Desktop/projectone/attendance-env/lib/python3.11/site-packages/flask/app.py", line 2190, in wsgi_app
    response = self.full_dispatch_request()
               ^^^^^^^^^^^^^^^^^^^^^^^^^^^^
  File "/Users/chaitanyaarora/Desktop/projectone/attendance-env/lib/python3.11/site-packages/flask/app.py", line 1486, in full_dispatch_request
    rv = self.handle_user_exception(e)
         ^^^^^^^^^^^^^^^^^^^^^^^^^^^^^
  File "/Users/chaitanyaarora/Desktop/projectone/attendance-env/lib/python3.11/site-packages/flask/app.py", line 1482, in full_dispatch_request
    rv = self.preprocess_request()
         ^^^^^^^^^^^^^^^^^^^^^^^^^
  File "/Users/chaitanyaarora/Desktop/projectone/attendance-env/lib/python3.11/site-packages/flask/app.py", line 1974, in preprocess_request
    rv = self.ensure_sync(before_func)()
         ^^^^^^^^^^^^^^^^^^^^^^^^^^^^^^^
  File "/Users/chaitanyaarora/Desktop/projectone/app.py", line 81, in before_first_request
    create_first_user()
  File "/Users/chaitanyaarora/Desktop/projectone/app.py", line 68, in create_first_user
    user_count = User.query.count()
                 ^^^^
NameError: name 'User' is not defined
2023-07-09 11:31:02,056 INFO: 127.0.0.1 - - [09/Jul/2023 11:31:02] "[35m[1mGET / HTTP/1.1[0m" 500 -
2023-07-09 11:31:02,098 ERROR: Exception on /favicon.ico [GET]
Traceback (most recent call last):
  File "/Users/chaitanyaarora/Desktop/projectone/attendance-env/lib/python3.11/site-packages/flask/app.py", line 2190, in wsgi_app
    response = self.full_dispatch_request()
               ^^^^^^^^^^^^^^^^^^^^^^^^^^^^
  File "/Users/chaitanyaarora/Desktop/projectone/attendance-env/lib/python3.11/site-packages/flask/app.py", line 1486, in full_dispatch_request
    rv = self.handle_user_exception(e)
         ^^^^^^^^^^^^^^^^^^^^^^^^^^^^^
  File "/Users/chaitanyaarora/Desktop/projectone/attendance-env/lib/python3.11/site-packages/flask/app.py", line 1482, in full_dispatch_request
    rv = self.preprocess_request()
         ^^^^^^^^^^^^^^^^^^^^^^^^^
  File "/Users/chaitanyaarora/Desktop/projectone/attendance-env/lib/python3.11/site-packages/flask/app.py", line 1974, in preprocess_request
    rv = self.ensure_sync(before_func)()
         ^^^^^^^^^^^^^^^^^^^^^^^^^^^^^^^
  File "/Users/chaitanyaarora/Desktop/projectone/app.py", line 81, in before_first_request
    create_first_user()
  File "/Users/chaitanyaarora/Desktop/projectone/app.py", line 68, in create_first_user
    user_count = User.query.count()
                 ^^^^
NameError: name 'User' is not defined
2023-07-09 11:31:02,099 INFO: 127.0.0.1 - - [09/Jul/2023 11:31:02] "[35m[1mGET /favicon.ico HTTP/1.1[0m" 500 -
2023-07-09 11:31:03,623 ERROR: Exception on / [GET]
Traceback (most recent call last):
  File "/Users/chaitanyaarora/Desktop/projectone/attendance-env/lib/python3.11/site-packages/flask/app.py", line 2190, in wsgi_app
    response = self.full_dispatch_request()
               ^^^^^^^^^^^^^^^^^^^^^^^^^^^^
  File "/Users/chaitanyaarora/Desktop/projectone/attendance-env/lib/python3.11/site-packages/flask/app.py", line 1486, in full_dispatch_request
    rv = self.handle_user_exception(e)
         ^^^^^^^^^^^^^^^^^^^^^^^^^^^^^
  File "/Users/chaitanyaarora/Desktop/projectone/attendance-env/lib/python3.11/site-packages/flask/app.py", line 1482, in full_dispatch_request
    rv = self.preprocess_request()
         ^^^^^^^^^^^^^^^^^^^^^^^^^
  File "/Users/chaitanyaarora/Desktop/projectone/attendance-env/lib/python3.11/site-packages/flask/app.py", line 1974, in preprocess_request
    rv = self.ensure_sync(before_func)()
         ^^^^^^^^^^^^^^^^^^^^^^^^^^^^^^^
  File "/Users/chaitanyaarora/Desktop/projectone/app.py", line 81, in before_first_request
    create_first_user()
  File "/Users/chaitanyaarora/Desktop/projectone/app.py", line 68, in create_first_user
    user_count = User.query.count()
                 ^^^^
NameError: name 'User' is not defined
2023-07-09 11:31:03,624 INFO: 127.0.0.1 - - [09/Jul/2023 11:31:03] "[35m[1mGET / HTTP/1.1[0m" 500 -
2023-07-09 11:31:03,666 ERROR: Exception on /favicon.ico [GET]
Traceback (most recent call last):
  File "/Users/chaitanyaarora/Desktop/projectone/attendance-env/lib/python3.11/site-packages/flask/app.py", line 2190, in wsgi_app
    response = self.full_dispatch_request()
               ^^^^^^^^^^^^^^^^^^^^^^^^^^^^
  File "/Users/chaitanyaarora/Desktop/projectone/attendance-env/lib/python3.11/site-packages/flask/app.py", line 1486, in full_dispatch_request
    rv = self.handle_user_exception(e)
         ^^^^^^^^^^^^^^^^^^^^^^^^^^^^^
  File "/Users/chaitanyaarora/Desktop/projectone/attendance-env/lib/python3.11/site-packages/flask/app.py", line 1482, in full_dispatch_request
    rv = self.preprocess_request()
         ^^^^^^^^^^^^^^^^^^^^^^^^^
  File "/Users/chaitanyaarora/Desktop/projectone/attendance-env/lib/python3.11/site-packages/flask/app.py", line 1974, in preprocess_request
    rv = self.ensure_sync(before_func)()
         ^^^^^^^^^^^^^^^^^^^^^^^^^^^^^^^
  File "/Users/chaitanyaarora/Desktop/projectone/app.py", line 81, in before_first_request
    create_first_user()
  File "/Users/chaitanyaarora/Desktop/projectone/app.py", line 68, in create_first_user
    user_count = User.query.count()
                 ^^^^
NameError: name 'User' is not defined
2023-07-09 11:31:03,667 INFO: 127.0.0.1 - - [09/Jul/2023 11:31:03] "[35m[1mGET /favicon.ico HTTP/1.1[0m" 500 -
2023-07-09 11:31:07,149 ERROR: Exception on /favicon.ico [GET]
Traceback (most recent call last):
  File "/Users/chaitanyaarora/Desktop/projectone/attendance-env/lib/python3.11/site-packages/flask/app.py", line 2190, in wsgi_app
    response = self.full_dispatch_request()
               ^^^^^^^^^^^^^^^^^^^^^^^^^^^^
  File "/Users/chaitanyaarora/Desktop/projectone/attendance-env/lib/python3.11/site-packages/flask/app.py", line 1486, in full_dispatch_request
    rv = self.handle_user_exception(e)
         ^^^^^^^^^^^^^^^^^^^^^^^^^^^^^
  File "/Users/chaitanyaarora/Desktop/projectone/attendance-env/lib/python3.11/site-packages/flask/app.py", line 1482, in full_dispatch_request
    rv = self.preprocess_request()
         ^^^^^^^^^^^^^^^^^^^^^^^^^
  File "/Users/chaitanyaarora/Desktop/projectone/attendance-env/lib/python3.11/site-packages/flask/app.py", line 1974, in preprocess_request
    rv = self.ensure_sync(before_func)()
         ^^^^^^^^^^^^^^^^^^^^^^^^^^^^^^^
  File "/Users/chaitanyaarora/Desktop/projectone/app.py", line 81, in before_first_request
    create_first_user()
  File "/Users/chaitanyaarora/Desktop/projectone/app.py", line 68, in create_first_user
    user_count = User.query.count()
                 ^^^^
NameError: name 'User' is not defined
2023-07-09 11:31:07,150 INFO: 127.0.0.1 - - [09/Jul/2023 11:31:07] "[35m[1mGET /favicon.ico HTTP/1.1[0m" 500 -
2023-07-09 11:31:19,884 ERROR: Exception on /students [GET]
Traceback (most recent call last):
  File "/Users/chaitanyaarora/Desktop/projectone/attendance-env/lib/python3.11/site-packages/flask/app.py", line 2190, in wsgi_app
    response = self.full_dispatch_request()
               ^^^^^^^^^^^^^^^^^^^^^^^^^^^^
  File "/Users/chaitanyaarora/Desktop/projectone/attendance-env/lib/python3.11/site-packages/flask/app.py", line 1486, in full_dispatch_request
    rv = self.handle_user_exception(e)
         ^^^^^^^^^^^^^^^^^^^^^^^^^^^^^
  File "/Users/chaitanyaarora/Desktop/projectone/attendance-env/lib/python3.11/site-packages/flask/app.py", line 1482, in full_dispatch_request
    rv = self.preprocess_request()
         ^^^^^^^^^^^^^^^^^^^^^^^^^
  File "/Users/chaitanyaarora/Desktop/projectone/attendance-env/lib/python3.11/site-packages/flask/app.py", line 1974, in preprocess_request
    rv = self.ensure_sync(before_func)()
         ^^^^^^^^^^^^^^^^^^^^^^^^^^^^^^^
  File "/Users/chaitanyaarora/Desktop/projectone/app.py", line 81, in before_first_request
    create_first_user()
  File "/Users/chaitanyaarora/Desktop/projectone/app.py", line 68, in create_first_user
    user_count = User.query.count()
                 ^^^^
NameError: name 'User' is not defined
2023-07-09 11:31:19,886 INFO: 127.0.0.1 - - [09/Jul/2023 11:31:19] "[35m[1mGET /students HTTP/1.1[0m" 500 -
2023-07-09 11:31:19,973 ERROR: Exception on /favicon.ico [GET]
Traceback (most recent call last):
  File "/Users/chaitanyaarora/Desktop/projectone/attendance-env/lib/python3.11/site-packages/flask/app.py", line 2190, in wsgi_app
    response = self.full_dispatch_request()
               ^^^^^^^^^^^^^^^^^^^^^^^^^^^^
  File "/Users/chaitanyaarora/Desktop/projectone/attendance-env/lib/python3.11/site-packages/flask/app.py", line 1486, in full_dispatch_request
    rv = self.handle_user_exception(e)
         ^^^^^^^^^^^^^^^^^^^^^^^^^^^^^
  File "/Users/chaitanyaarora/Desktop/projectone/attendance-env/lib/python3.11/site-packages/flask/app.py", line 1482, in full_dispatch_request
    rv = self.preprocess_request()
         ^^^^^^^^^^^^^^^^^^^^^^^^^
  File "/Users/chaitanyaarora/Desktop/projectone/attendance-env/lib/python3.11/site-packages/flask/app.py", line 1974, in preprocess_request
    rv = self.ensure_sync(before_func)()
         ^^^^^^^^^^^^^^^^^^^^^^^^^^^^^^^
  File "/Users/chaitanyaarora/Desktop/projectone/app.py", line 81, in before_first_request
    create_first_user()
  File "/Users/chaitanyaarora/Desktop/projectone/app.py", line 68, in create_first_user
    user_count = User.query.count()
                 ^^^^
NameError: name 'User' is not defined
2023-07-09 11:31:19,974 INFO: 127.0.0.1 - - [09/Jul/2023 11:31:19] "[35m[1mGET /favicon.ico HTTP/1.1[0m" 500 -
2023-07-09 12:34:20,309 INFO: [31m[1mWARNING: This is a development server. Do not use it in a production deployment. Use a production WSGI server instead.[0m
 * Running on http://127.0.0.1:5000
2023-07-09 12:34:20,309 INFO: [33mPress CTRL+C to quit[0m
2023-07-09 12:34:31,516 ERROR: Exception on /users [GET]
Traceback (most recent call last):
  File "/Users/chaitanyaarora/Desktop/projectone/attendance-env/lib/python3.11/site-packages/flask/app.py", line 2190, in wsgi_app
    response = self.full_dispatch_request()
               ^^^^^^^^^^^^^^^^^^^^^^^^^^^^
  File "/Users/chaitanyaarora/Desktop/projectone/attendance-env/lib/python3.11/site-packages/flask/app.py", line 1486, in full_dispatch_request
    rv = self.handle_user_exception(e)
         ^^^^^^^^^^^^^^^^^^^^^^^^^^^^^
  File "/Users/chaitanyaarora/Desktop/projectone/attendance-env/lib/python3.11/site-packages/flask/app.py", line 1482, in full_dispatch_request
    rv = self.preprocess_request()
         ^^^^^^^^^^^^^^^^^^^^^^^^^
  File "/Users/chaitanyaarora/Desktop/projectone/attendance-env/lib/python3.11/site-packages/flask/app.py", line 1974, in preprocess_request
    rv = self.ensure_sync(before_func)()
         ^^^^^^^^^^^^^^^^^^^^^^^^^^^^^^^
  File "/Users/chaitanyaarora/Desktop/projectone/app.py", line 81, in before_first_request
    create_first_user()
  File "/Users/chaitanyaarora/Desktop/projectone/app.py", line 68, in create_first_user
    user_count = User.query.count()
                 ^^^^
NameError: name 'User' is not defined
2023-07-09 12:34:31,520 INFO: 127.0.0.1 - - [09/Jul/2023 12:34:31] "[35m[1mGET /users HTTP/1.1[0m" 500 -
2023-07-09 12:34:31,618 ERROR: Exception on /favicon.ico [GET]
Traceback (most recent call last):
  File "/Users/chaitanyaarora/Desktop/projectone/attendance-env/lib/python3.11/site-packages/flask/app.py", line 2190, in wsgi_app
    response = self.full_dispatch_request()
               ^^^^^^^^^^^^^^^^^^^^^^^^^^^^
  File "/Users/chaitanyaarora/Desktop/projectone/attendance-env/lib/python3.11/site-packages/flask/app.py", line 1486, in full_dispatch_request
    rv = self.handle_user_exception(e)
         ^^^^^^^^^^^^^^^^^^^^^^^^^^^^^
  File "/Users/chaitanyaarora/Desktop/projectone/attendance-env/lib/python3.11/site-packages/flask/app.py", line 1482, in full_dispatch_request
    rv = self.preprocess_request()
         ^^^^^^^^^^^^^^^^^^^^^^^^^
  File "/Users/chaitanyaarora/Desktop/projectone/attendance-env/lib/python3.11/site-packages/flask/app.py", line 1974, in preprocess_request
    rv = self.ensure_sync(before_func)()
         ^^^^^^^^^^^^^^^^^^^^^^^^^^^^^^^
  File "/Users/chaitanyaarora/Desktop/projectone/app.py", line 81, in before_first_request
    create_first_user()
  File "/Users/chaitanyaarora/Desktop/projectone/app.py", line 68, in create_first_user
    user_count = User.query.count()
                 ^^^^
NameError: name 'User' is not defined
2023-07-09 12:34:31,619 INFO: 127.0.0.1 - - [09/Jul/2023 12:34:31] "[35m[1mGET /favicon.ico HTTP/1.1[0m" 500 -
2023-07-09 12:49:47,821 ERROR: Exception on /users [GET]
Traceback (most recent call last):
  File "/Users/chaitanyaarora/Desktop/projectone/attendance-env/lib/python3.11/site-packages/flask/app.py", line 2190, in wsgi_app
    response = self.full_dispatch_request()
               ^^^^^^^^^^^^^^^^^^^^^^^^^^^^
  File "/Users/chaitanyaarora/Desktop/projectone/attendance-env/lib/python3.11/site-packages/flask/app.py", line 1486, in full_dispatch_request
    rv = self.handle_user_exception(e)
         ^^^^^^^^^^^^^^^^^^^^^^^^^^^^^
  File "/Users/chaitanyaarora/Desktop/projectone/attendance-env/lib/python3.11/site-packages/flask/app.py", line 1482, in full_dispatch_request
    rv = self.preprocess_request()
         ^^^^^^^^^^^^^^^^^^^^^^^^^
  File "/Users/chaitanyaarora/Desktop/projectone/attendance-env/lib/python3.11/site-packages/flask/app.py", line 1974, in preprocess_request
    rv = self.ensure_sync(before_func)()
         ^^^^^^^^^^^^^^^^^^^^^^^^^^^^^^^
  File "/Users/chaitanyaarora/Desktop/projectone/app.py", line 81, in before_first_request
    create_first_user()
  File "/Users/chaitanyaarora/Desktop/projectone/app.py", line 68, in create_first_user
    user_count = User.query.count()
                 ^^^^
NameError: name 'User' is not defined
2023-07-09 12:49:47,827 INFO: 127.0.0.1 - - [09/Jul/2023 12:49:47] "[35m[1mGET /users HTTP/1.1[0m" 500 -
2023-07-09 12:49:47,873 ERROR: Exception on /favicon.ico [GET]
Traceback (most recent call last):
  File "/Users/chaitanyaarora/Desktop/projectone/attendance-env/lib/python3.11/site-packages/flask/app.py", line 2190, in wsgi_app
    response = self.full_dispatch_request()
               ^^^^^^^^^^^^^^^^^^^^^^^^^^^^
  File "/Users/chaitanyaarora/Desktop/projectone/attendance-env/lib/python3.11/site-packages/flask/app.py", line 1486, in full_dispatch_request
    rv = self.handle_user_exception(e)
         ^^^^^^^^^^^^^^^^^^^^^^^^^^^^^
  File "/Users/chaitanyaarora/Desktop/projectone/attendance-env/lib/python3.11/site-packages/flask/app.py", line 1482, in full_dispatch_request
    rv = self.preprocess_request()
         ^^^^^^^^^^^^^^^^^^^^^^^^^
  File "/Users/chaitanyaarora/Desktop/projectone/attendance-env/lib/python3.11/site-packages/flask/app.py", line 1974, in preprocess_request
    rv = self.ensure_sync(before_func)()
         ^^^^^^^^^^^^^^^^^^^^^^^^^^^^^^^
  File "/Users/chaitanyaarora/Desktop/projectone/app.py", line 81, in before_first_request
    create_first_user()
  File "/Users/chaitanyaarora/Desktop/projectone/app.py", line 68, in create_first_user
    user_count = User.query.count()
                 ^^^^
NameError: name 'User' is not defined
2023-07-09 12:49:47,874 INFO: 127.0.0.1 - - [09/Jul/2023 12:49:47] "[35m[1mGET /favicon.ico HTTP/1.1[0m" 500 -
2023-07-09 12:50:08,010 ERROR: Exception on /users [GET]
Traceback (most recent call last):
  File "/Users/chaitanyaarora/Desktop/projectone/attendance-env/lib/python3.11/site-packages/flask/app.py", line 2190, in wsgi_app
    response = self.full_dispatch_request()
               ^^^^^^^^^^^^^^^^^^^^^^^^^^^^
  File "/Users/chaitanyaarora/Desktop/projectone/attendance-env/lib/python3.11/site-packages/flask/app.py", line 1486, in full_dispatch_request
    rv = self.handle_user_exception(e)
         ^^^^^^^^^^^^^^^^^^^^^^^^^^^^^
  File "/Users/chaitanyaarora/Desktop/projectone/attendance-env/lib/python3.11/site-packages/flask/app.py", line 1482, in full_dispatch_request
    rv = self.preprocess_request()
         ^^^^^^^^^^^^^^^^^^^^^^^^^
  File "/Users/chaitanyaarora/Desktop/projectone/attendance-env/lib/python3.11/site-packages/flask/app.py", line 1974, in preprocess_request
    rv = self.ensure_sync(before_func)()
         ^^^^^^^^^^^^^^^^^^^^^^^^^^^^^^^
  File "/Users/chaitanyaarora/Desktop/projectone/app.py", line 81, in before_first_request
    create_first_user()
  File "/Users/chaitanyaarora/Desktop/projectone/app.py", line 68, in create_first_user
    user_count = User.query.count()
                 ^^^^
NameError: name 'User' is not defined
2023-07-09 12:50:08,012 INFO: 127.0.0.1 - - [09/Jul/2023 12:50:08] "[35m[1mGET /users HTTP/1.1[0m" 500 -
2023-07-09 12:50:08,044 ERROR: Exception on /favicon.ico [GET]
Traceback (most recent call last):
  File "/Users/chaitanyaarora/Desktop/projectone/attendance-env/lib/python3.11/site-packages/flask/app.py", line 2190, in wsgi_app
    response = self.full_dispatch_request()
               ^^^^^^^^^^^^^^^^^^^^^^^^^^^^
  File "/Users/chaitanyaarora/Desktop/projectone/attendance-env/lib/python3.11/site-packages/flask/app.py", line 1486, in full_dispatch_request
    rv = self.handle_user_exception(e)
         ^^^^^^^^^^^^^^^^^^^^^^^^^^^^^
  File "/Users/chaitanyaarora/Desktop/projectone/attendance-env/lib/python3.11/site-packages/flask/app.py", line 1482, in full_dispatch_request
    rv = self.preprocess_request()
         ^^^^^^^^^^^^^^^^^^^^^^^^^
  File "/Users/chaitanyaarora/Desktop/projectone/attendance-env/lib/python3.11/site-packages/flask/app.py", line 1974, in preprocess_request
    rv = self.ensure_sync(before_func)()
         ^^^^^^^^^^^^^^^^^^^^^^^^^^^^^^^
  File "/Users/chaitanyaarora/Desktop/projectone/app.py", line 81, in before_first_request
    create_first_user()
  File "/Users/chaitanyaarora/Desktop/projectone/app.py", line 68, in create_first_user
    user_count = User.query.count()
                 ^^^^
NameError: name 'User' is not defined
2023-07-09 12:50:08,045 INFO: 127.0.0.1 - - [09/Jul/2023 12:50:08] "[35m[1mGET /favicon.ico HTTP/1.1[0m" 500 -
2023-07-09 13:42:21,114 INFO: [31m[1mWARNING: This is a development server. Do not use it in a production deployment. Use a production WSGI server instead.[0m
 * Running on http://127.0.0.1:5000
2023-07-09 13:42:21,114 INFO: [33mPress CTRL+C to quit[0m
2023-07-09 13:42:29,815 ERROR: Exception on /users [GET]
Traceback (most recent call last):
  File "/Users/chaitanyaarora/Desktop/projectone/attendance-env/lib/python3.11/site-packages/flask/app.py", line 2190, in wsgi_app
    response = self.full_dispatch_request()
               ^^^^^^^^^^^^^^^^^^^^^^^^^^^^
  File "/Users/chaitanyaarora/Desktop/projectone/attendance-env/lib/python3.11/site-packages/flask/app.py", line 1486, in full_dispatch_request
    rv = self.handle_user_exception(e)
         ^^^^^^^^^^^^^^^^^^^^^^^^^^^^^
  File "/Users/chaitanyaarora/Desktop/projectone/attendance-env/lib/python3.11/site-packages/flask/app.py", line 1482, in full_dispatch_request
    rv = self.preprocess_request()
         ^^^^^^^^^^^^^^^^^^^^^^^^^
  File "/Users/chaitanyaarora/Desktop/projectone/attendance-env/lib/python3.11/site-packages/flask/app.py", line 1974, in preprocess_request
    rv = self.ensure_sync(before_func)()
         ^^^^^^^^^^^^^^^^^^^^^^^^^^^^^^^
  File "/Users/chaitanyaarora/Desktop/projectone/app.py", line 81, in before_first_request
    create_first_user()
  File "/Users/chaitanyaarora/Desktop/projectone/app.py", line 68, in create_first_user
    user_count = User.query.count()
                 ^^^^
NameError: name 'User' is not defined
2023-07-09 13:42:29,818 INFO: 127.0.0.1 - - [09/Jul/2023 13:42:29] "[35m[1mGET /users HTTP/1.1[0m" 500 -
2023-07-09 13:42:29,983 ERROR: Exception on /favicon.ico [GET]
Traceback (most recent call last):
  File "/Users/chaitanyaarora/Desktop/projectone/attendance-env/lib/python3.11/site-packages/flask/app.py", line 2190, in wsgi_app
    response = self.full_dispatch_request()
               ^^^^^^^^^^^^^^^^^^^^^^^^^^^^
  File "/Users/chaitanyaarora/Desktop/projectone/attendance-env/lib/python3.11/site-packages/flask/app.py", line 1486, in full_dispatch_request
    rv = self.handle_user_exception(e)
         ^^^^^^^^^^^^^^^^^^^^^^^^^^^^^
  File "/Users/chaitanyaarora/Desktop/projectone/attendance-env/lib/python3.11/site-packages/flask/app.py", line 1482, in full_dispatch_request
    rv = self.preprocess_request()
         ^^^^^^^^^^^^^^^^^^^^^^^^^
  File "/Users/chaitanyaarora/Desktop/projectone/attendance-env/lib/python3.11/site-packages/flask/app.py", line 1974, in preprocess_request
    rv = self.ensure_sync(before_func)()
         ^^^^^^^^^^^^^^^^^^^^^^^^^^^^^^^
  File "/Users/chaitanyaarora/Desktop/projectone/app.py", line 81, in before_first_request
    create_first_user()
  File "/Users/chaitanyaarora/Desktop/projectone/app.py", line 68, in create_first_user
    user_count = User.query.count()
                 ^^^^
NameError: name 'User' is not defined
2023-07-09 13:42:29,984 INFO: 127.0.0.1 - - [09/Jul/2023 13:42:29] "[35m[1mGET /favicon.ico HTTP/1.1[0m" 500 -
